File: XRD/example_data/texture map/texture.xrdml
<xrdMeasurements xmlns="http://www.xrdml.com/XRDMeasurement/2.1" xmlns:xsi="http://www.w3.org/2001/XMLSchema-instance" xsi:schemaLocation="http://www.xrdml.com/XRDMeasurement/2.1 http://www.xrdml.com/XRDMeasurement/2.1/XRDMeasurement.xsd" status="Completed">
	<comment>
		<entry>Configuration=Factoryconfiguration, Owner=User-1, Creation date=5/27/2010 1:30:43 PM</entry>
		<entry>Goniometer=PW3050/65 (Theta/2Theta); Minimum step size 2Theta:0.0001; Minimum step size Omega:0.0001</entry>
		<entry>Sample stage=MRD Cradle; Minimum step size Phi:0.01; Minimum step size Chi:0.01; Minimum step size X:0.01; Minimum step size Y:0.01; Minimum step size Z:0.001</entry>
		<entry>Diffractometer system=XPERT-PRO</entry>
		<entry>Measurement program=C:\PANalytical\Data Collector\Programs\patrick_texture.xrdmp, Identifier={DB9029F8-E0BE-4653-9DB1-5C4574A33A56}</entry>
		<entry>Fine Calibration Offset for 2Theta = -0.0218 deg</entry>
	</comment>
	<sample type="To be analyzed">
		<id></id>
		<name></name>
		<preparedBy></preparedBy>
	</sample>
	<xrdMeasurement measurementType="Texture pole figure" status="Completed" measurementStepAxis="Chi" sampleMode="Reflection">
		<comment>
			<entry>InAs220, psi 0 to 90</entry>
			<entry>PHD Lower Level = 4.10 (keV), PHD Upper Level = 16.10 (keV)</entry>
		</comment>
		<usedWavelength intended="K-Alpha 1">
			<kAlpha1 unit="Angstrom">1.5405980</kAlpha1>
			<kAlpha2 unit="Angstrom">1.5444260</kAlpha2>
			<kBeta unit="Angstrom">1.3922500</kBeta>
			<ratioKAlpha2KAlpha1>0.5000</ratioKAlpha2KAlpha1>
		</usedWavelength>
		<incidentBeamPath>
			<radius unit="mm">320.00</radius>
			<xRayTube id="1010048" name="Empyrean Cu LFF HR (9430 033 7310x) DK421803">
				<tension unit="kV">40.0</tension>
				<current unit="mA">40.0</current>
				<anodeMaterial>Cu</anodeMaterial>
				<focus type="Line">
					<length unit="mm">12.0</length>
					<width unit="mm">0.4</width>
					<takeOffAngle unit="deg">4.5</takeOffAngle>
				</focus>
			</xRayTube>
			<xRayMirror id="27090001" name="Inc. Beam Cu W/Si (hybrid MRD)" hybrid="true">
				<crystal type="Graded" shape="Parabolic">W/Si</crystal>
				<acceptanceAngle unit="deg">0.800</acceptanceAngle>
				<length unit="mm">60.0</length>
			</xRayMirror>
			<monochromator id="23090002" name="Hybrid monochr. 2xGe(220) Cu asym." hybrid="true">
				<crystal type="Asymmetric" shape="Flat">Ge</crystal>
				<numberOfReflections>2</numberOfReflections>
				<hkl>
					<h>2</h>
					<k>2</k>
					<l>0</l>
				</hkl>
			</monochromator>
			<sollerSlit id="21010002" name="Soller slits 0.04 rad.">
				<opening unit="rad">0.0400</opening>
			</sollerSlit>
			<mask id="22030008" name="Fixed mask 4 mm">
				<width unit="mm">4.00</width>
			</mask>
			<divergenceSlit id="22010004" name="Fixed slit 1/2°" xsi:type="fixedDivergenceSlitType">
				<distanceToSample unit="mm">220.00</distanceToSample>
				<height unit="mm">0.76</height>
			</divergenceSlit>
		</incidentBeamPath>
		<sampleOffset>
			<position axis="2Theta" unit="deg">0.0000</position>
			<position axis="Omega" unit="deg">0.0000</position>
		</sampleOffset>
		<diffractedBeamPath>
			<radius unit="mm">320.00</radius>
			<parallelPlateCollimator id="25010002" name="Parallel plate collimator 0.18°">
				<opening unit="deg">0.18</opening>
			</parallelPlateCollimator>
			<detector id="7010015" name="PIXcel1D detector" xsi:type="rtmsDetectorType">
				<phd unit="%">
					<lowerLevel>25.5</lowerLevel>
					<upperLevel>100.0</upperLevel>
				</phd>
				<mode>Receiving slit</mode>
				<activeLength unit="mm">0.16</activeLength>
			</detector>
		</diffractedBeamPath>
		<scan appendNumber="0" mode="Continuous" scanAxis="Phi" status="Completed">
			<header>
				<startTimeStamp>2020-09-09T10:46:44+02:00</startTimeStamp>
				<endTimeStamp>2020-09-09T10:49:46+02:00</endTimeStamp>
				<author>
					<name>User</name>
				</author>
				<source>
					<applicationSoftware version="6.1">Data Collector</applicationSoftware>
					<instrumentControlSoftware version="2.2F 20161117">XPERT-PRO</instrumentControlSoftware>
					<instrumentID>0000000011073629</instrumentID>
				</source>
			</header>
			<dataPoints>
				<positions axis="2Theta" unit="deg">
					<commonPosition>29.8800</commonPosition>
				</positions>
				<positions axis="Omega" unit="deg">
					<commonPosition>14.9400</commonPosition>
				</positions>
				<positions axis="Phi" unit="deg">
					<startPosition>0.50</startPosition>
					<endPosition>359.50</endPosition>
				</positions>
				<positions axis="Chi" unit="deg">
					<commonPosition>0.00</commonPosition>
				</positions>
				<positions axis="X" unit="mm">
					<commonPosition>-1.57</commonPosition>
				</positions>
				<positions axis="Y" unit="mm">
					<commonPosition>0.80</commonPosition>
				</positions>
				<positions axis="Z" unit="mm">
					<commonPosition>6.427</commonPosition>
				</positions>
				<commonCountingTime unit="seconds">0.440</commonCountingTime>
				<counts unit="counts">5 4 7 2 5 5 8 4 5 4 7 2 5 3 3 5 1 7 5 2 6 4 4 3 2 4 0 2 2 3 5 1 4 5 5 4 2 7 3 1 1 2 5 5 3 6 1 4 4 1 2 6 0 6 2 4 3 8 1 2 3 4 1 3 4 5 4 6 5 0 0 0 6 4 4 8 2 1 1 3 4 2 2 4 3 7 7 6 6 9 4 4 2 2 2 6 3 6 0 6 10 3 4 5 9 1 1 2 6 4 2 1 3 2 3 3 2 2 1 4 5 7 3 3 1 2 2 2 4 2 6 2 2 5 3 2 5 6 2 3 7 2 7 1 5 8 2 3 7 4 5 7 4 6 1 4 3 5 6 3 3 1 6 4 2 6 5 3 5 4 5 2 5 1 0 8 5 3 4 2 5 5 7 6 2 5 4 3 4 1 3 5 2 4 5 4 4 1 7 4 6 1 5 3 1 2 4 4 4 2 1 3 2 1 2 2 3 2 3 1 1 2 5 4 1 2 1 4 1 1 6 7 3 6 7 3 2 2 2 4 2 4 6 6 5 3 8 4 6 8 3 3 7 5 3 2 2 5 1 4 4 3 6 5 6 3 7 4 5 5 0 7 2 2 10 4 3 3 4 2 3 5 4 4 1 0 1 2 4 0 2 4 2 4 5 3 2 4 5 7 7 5 6 7 7 3 5 5 6 3 3 0 3 0 4 3 3 4 3 2 1 6 5 1 6 3 2 3 3 7 4 4 4 3 3 3 4 4 3 6 9 5 5 9 3 10 2 2 1 4 3 4 5 6 3 6 11 4 3 7</counts>
			</dataPoints>
		</scan>
		<scan appendNumber="0" mode="Continuous" scanAxis="Phi" status="Completed">
			<header>
				<startTimeStamp>2020-09-09T10:49:57+02:00</startTimeStamp>
				<endTimeStamp>2020-09-09T10:52:59+02:00</endTimeStamp>
				<author>
					<name>User</name>
				</author>
				<source>
					<applicationSoftware version="6.1">Data Collector</applicationSoftware>
					<instrumentControlSoftware version="2.2F 20161117">XPERT-PRO</instrumentControlSoftware>
					<instrumentID>0000000011073629</instrumentID>
				</source>
			</header>
			<dataPoints>
				<positions axis="2Theta" unit="deg">
					<commonPosition>29.8800</commonPosition>
				</positions>
				<positions axis="Omega" unit="deg">
					<commonPosition>14.9400</commonPosition>
				</positions>
				<positions axis="Phi" unit="deg">
					<startPosition>0.50</startPosition>
					<endPosition>359.50</endPosition>
				</positions>
				<positions axis="Chi" unit="deg">
					<commonPosition>2.00</commonPosition>
				</positions>
				<positions axis="X" unit="mm">
					<commonPosition>-1.57</commonPosition>
				</positions>
				<positions axis="Y" unit="mm">
					<commonPosition>0.80</commonPosition>
				</positions>
				<positions axis="Z" unit="mm">
					<commonPosition>6.427</commonPosition>
				</positions>
				<commonCountingTime unit="seconds">0.440</commonCountingTime>
				<counts unit="counts">1 4 6 3 4 6 1 4 6 6 2 1 1 2 3 2 2 7 3 2 4 3 4 4 0 5 1 4 7 4 0 4 5 3 4 1 5 5 4 2 5 4 5 5 3 2 7 8 0 3 2 3 7 8 1 1 5 2 5 4 4 1 5 5 5 7 1 4 2 4 5 4 5 4 1 3 6 4 3 3 6 3 2 1 3 1 1 8 3 6 5 4 3 0 3 4 0 6 2 5 7 1 3 5 2 7 1 5 1 2 5 3 2 1 5 3 5 6 4 5 1 8 3 2 0 0 4 5 4 1 2 0 5 3 2 4 5 2 7 5 4 5 6 3 1 8 3 5 4 2 5 5 5 4 0 3 3 4 7 1 4 3 3 2 7 2 6 6 10 6 6 5 7 1 2 3 6 5 2 3 7 4 4 3 5 5 5 4 11 9 5 1 5 1 3 2 3 6 4 5 6 1 1 5 4 6 4 3 3 3 7 4 3 7 4 4 3 3 3 4 1 1 3 1 5 4 1 1 1 5 9 4 3 5 4 3 2 4 7 4 0 4 2 3 3 3 4 2 3 8 4 3 5 2 3 5 7 4 2 3 4 1 0 4 1 2 4 2 0 5 4 1 2 2 4 3 4 1 2 8 4 1 4 7 5 2 2 8 2 1 4 4 7 1 4 2 3 6 3 3 2 5 5 4 3 2 5 3 3 6 4 1 5 1 4 2 1 5 2 4 3 5 3 5 1 2 7 4 6 6 4 4 6 5 5 1 2 4 3 4 3 5 2 4 4 2 1 3 1 7 9 4 1 6 0 7 2 4 2 5</counts>
			</dataPoints>
		</scan>
		<scan appendNumber="0" mode="Continuous" scanAxis="Phi" status="Completed">
			<header>
				<startTimeStamp>2020-09-09T10:53:10+02:00</startTimeStamp>
				<endTimeStamp>2020-09-09T10:56:12+02:00</endTimeStamp>
				<author>
					<name>User</name>
				</author>
				<source>
					<applicationSoftware version="6.1">Data Collector</applicationSoftware>
					<instrumentControlSoftware version="2.2F 20161117">XPERT-PRO</instrumentControlSoftware>
					<instrumentID>0000000011073629</instrumentID>
				</source>
			</header>
			<dataPoints>
				<positions axis="2Theta" unit="deg">
					<commonPosition>29.8800</commonPosition>
				</positions>
				<positions axis="Omega" unit="deg">
					<commonPosition>14.9400</commonPosition>
				</positions>
				<positions axis="Phi" unit="deg">
					<startPosition>0.50</startPosition>
					<endPosition>359.50</endPosition>
				</positions>
				<positions axis="Chi" unit="deg">
					<commonPosition>4.00</commonPosition>
				</positions>
				<positions axis="X" unit="mm">
					<commonPosition>-1.57</commonPosition>
				</positions>
				<positions axis="Y" unit="mm">
					<commonPosition>0.80</commonPosition>
				</positions>
				<positions axis="Z" unit="mm">
					<commonPosition>6.427</commonPosition>
				</positions>
				<commonCountingTime unit="seconds">0.440</commonCountingTime>
				<counts unit="counts">3 3 7 6 6 2 3 3 6 9 5 1 1 4 4 2 1 3 3 2 4 1 9 8 5 6 4 0 5 1 4 2 1 1 4 1 7 4 0 2 1 5 4 1 6 1 2 1 2 4 1 9 6 5 4 2 3 3 1 4 1 5 5 1 1 5 4 2 3 1 3 4 4 2 6 5 2 1 1 6 3 1 6 4 6 2 3 6 3 2 8 1 4 5 4 7 7 3 1 4 1 1 2 4 2 4 5 4 4 1 4 3 4 4 2 2 3 5 4 4 3 6 6 0 4 0 4 1 3 2 4 1 7 6 6 4 6 9 8 7 2 5 7 7 3 2 4 2 2 3 5 1 4 4 1 5 2 2 6 3 2 4 2 6 1 10 5 3 3 4 4 5 1 6 10 7 4 0 2 3 2 4 4 5 7 4 2 3 3 5 0 2 4 4 4 5 2 2 7 1 1 4 4 5 2 2 2 0 6 4 2 5 3 3 0 4 4 5 6 2 3 1 1 1 1 5 3 4 5 4 6 4 2 5 6 3 1 1 1 6 2 3 7 2 7 2 6 1 4 4 5 1 4 1 2 3 4 4 2 9 5 3 7 6 3 3 2 3 1 5 5 5 3 4 4 3 5 2 7 5 1 2 5 4 1 3 6 6 6 4 3 5 5 2 1 4 2 1 6 3 2 3 0 2 4 1 5 4 4 3 2 2 2 3 7 1 5 2 1 2 3 3 5 1 7 2 8 7 7 4 1 3 4 2 3 2 5 1 4 2 1 2 5 8 4 3 4 7 4 5 1 1 6 3 3 3 4 7 1 4</counts>
			</dataPoints>
		</scan>
		<scan appendNumber="0" mode="Continuous" scanAxis="Phi" status="Completed">
			<header>
				<startTimeStamp>2020-09-09T10:56:23+02:00</startTimeStamp>
				<endTimeStamp>2020-09-09T10:59:25+02:00</endTimeStamp>
				<author>
					<name>User</name>
				</author>
				<source>
					<applicationSoftware version="6.1">Data Collector</applicationSoftware>
					<instrumentControlSoftware version="2.2F 20161117">XPERT-PRO</instrumentControlSoftware>
					<instrumentID>0000000011073629</instrumentID>
				</source>
			</header>
			<dataPoints>
				<positions axis="2Theta" unit="deg">
					<commonPosition>29.8800</commonPosition>
				</positions>
				<positions axis="Omega" unit="deg">
					<commonPosition>14.9400</commonPosition>
				</positions>
				<positions axis="Phi" unit="deg">
					<startPosition>0.50</startPosition>
					<endPosition>359.50</endPosition>
				</positions>
				<positions axis="Chi" unit="deg">
					<commonPosition>6.00</commonPosition>
				</positions>
				<positions axis="X" unit="mm">
					<commonPosition>-1.57</commonPosition>
				</positions>
				<positions axis="Y" unit="mm">
					<commonPosition>0.80</commonPosition>
				</positions>
				<positions axis="Z" unit="mm">
					<commonPosition>6.427</commonPosition>
				</positions>
				<commonCountingTime unit="seconds">0.440</commonCountingTime>
				<counts unit="counts">4 5 3 4 2 2 6 5 2 2 5 4 3 2 2 3 5 6 1 6 2 4 3 3 3 2 0 6 1 8 1 3 1 4 3 2 1 1 4 2 7 5 4 3 3 1 2 3 6 4 5 3 2 1 1 3 1 5 2 4 0 5 3 6 1 2 3 4 3 3 6 3 4 2 2 4 8 3 4 6 4 4 1 5 5 5 3 5 1 4 8 1 5 2 4 7 4 5 4 1 1 3 3 7 6 2 7 3 8 4 5 2 5 4 1 5 4 6 8 3 5 5 1 9 5 1 3 4 3 2 6 2 7 5 1 6 6 3 3 4 2 3 4 6 4 8 1 0 6 1 4 7 2 4 7 2 4 6 6 0 2 1 4 3 4 4 1 10 5 9 3 1 5 6 4 4 3 5 4 4 2 8 3 5 2 4 2 10 1 2 3 4 1 4 0 5 6 4 3 4 3 4 4 2 5 7 3 1 0 4 4 4 4 3 1 4 2 2 2 1 4 1 1 5 2 4 1 1 5 2 4 4 2 6 2 6 2 4 5 2 3 3 0 7 2 3 4 1 3 1 6 2 5 3 5 4 3 1 1 5 2 3 7 1 1 5 6 3 5 1 4 2 6 2 1 4 1 1 4 4 7 4 6 2 4 2 2 1 1 4 4 7 1 3 4 2 2 3 3 1 0 3 1 5 4 3 2 6 1 3 1 5 4 1 2 2 1 1 5 7 6 3 2 6 2 5 1 3 2 5 4 4 3 2 1 1 5 4 4 1 2 5 9 1 2 5 1 1 1 6 3 2 7 3 4 3 1 4 5 5</counts>
			</dataPoints>
		</scan>
		<scan appendNumber="0" mode="Continuous" scanAxis="Phi" status="Completed">
			<header>
				<startTimeStamp>2020-09-09T10:59:35+02:00</startTimeStamp>
				<endTimeStamp>2020-09-09T11:02:38+02:00</endTimeStamp>
				<author>
					<name>User</name>
				</author>
				<source>
					<applicationSoftware version="6.1">Data Collector</applicationSoftware>
					<instrumentControlSoftware version="2.2F 20161117">XPERT-PRO</instrumentControlSoftware>
					<instrumentID>0000000011073629</instrumentID>
				</source>
			</header>
			<dataPoints>
				<positions axis="2Theta" unit="deg">
					<commonPosition>29.8800</commonPosition>
				</positions>
				<positions axis="Omega" unit="deg">
					<commonPosition>14.9400</commonPosition>
				</positions>
				<positions axis="Phi" unit="deg">
					<startPosition>0.50</startPosition>
					<endPosition>359.50</endPosition>
				</positions>
				<positions axis="Chi" unit="deg">
					<commonPosition>8.00</commonPosition>
				</positions>
				<positions axis="X" unit="mm">
					<commonPosition>-1.57</commonPosition>
				</positions>
				<positions axis="Y" unit="mm">
					<commonPosition>0.80</commonPosition>
				</positions>
				<positions axis="Z" unit="mm">
					<commonPosition>6.427</commonPosition>
				</positions>
				<commonCountingTime unit="seconds">0.440</commonCountingTime>
				<counts unit="counts">2 5 2 10 4 2 4 0 4 0 3 0 1 4 7 3 6 7 7 3 1 6 4 7 3 2 1 2 5 1 5 5 0 1 8 4 3 4 2 4 4 2 4 4 5 1 5 1 4 3 5 1 3 4 3 6 3 4 3 4 2 3 4 1 3 3 1 2 4 1 6 5 2 5 6 5 1 4 5 3 4 3 6 3 4 2 2 5 1 6 2 6 1 7 3 3 4 2 3 3 4 6 4 1 5 4 2 3 6 8 5 3 6 3 7 7 0 1 4 1 3 0 1 3 7 1 3 3 3 1 4 1 10 3 4 4 4 3 5 2 4 6 3 3 4 8 3 1 1 6 1 4 3 1 4 1 3 4 5 6 3 1 4 6 3 1 4 4 6 3 3 5 5 3 0 6 1 2 5 8 2 6 5 9 2 3 3 3 6 5 2 9 5 1 8 5 5 10 1 3 3 2 1 5 0 4 0 6 6 4 4 3 3 1 4 4 4 2 0 3 3 5 4 2 3 1 3 5 0 6 6 5 2 3 1 4 2 2 2 0 4 5 2 6 1 3 3 4 4 3 3 0 2 5 4 6 2 4 2 2 2 6 1 1 4 2 4 2 0 4 1 1 3 3 1 2 1 6 4 3 2 1 1 5 5 2 2 4 3 4 4 2 3 7 2 3 5 1 3 5 4 2 8 3 10 1 3 2 2 4 0 5 6 3 0 4 2 5 7 4 5 1 3 2 7 2 4 1 3 1 3 3 1 1 5 1 2 2 4 10 1 2 4 6 5 6 2 4 3 7 0 3 8 6 0 2 9 1 2 4</counts>
			</dataPoints>
		</scan>
		<scan appendNumber="0" mode="Continuous" scanAxis="Phi" status="Completed">
			<header>
				<startTimeStamp>2020-09-09T11:02:48+02:00</startTimeStamp>
				<endTimeStamp>2020-09-09T11:05:50+02:00</endTimeStamp>
				<author>
					<name>User</name>
				</author>
				<source>
					<applicationSoftware version="6.1">Data Collector</applicationSoftware>
					<instrumentControlSoftware version="2.2F 20161117">XPERT-PRO</instrumentControlSoftware>
					<instrumentID>0000000011073629</instrumentID>
				</source>
			</header>
			<dataPoints>
				<positions axis="2Theta" unit="deg">
					<commonPosition>29.8800</commonPosition>
				</positions>
				<positions axis="Omega" unit="deg">
					<commonPosition>14.9400</commonPosition>
				</positions>
				<positions axis="Phi" unit="deg">
					<startPosition>0.50</startPosition>
					<endPosition>359.50</endPosition>
				</positions>
				<positions axis="Chi" unit="deg">
					<commonPosition>10.00</commonPosition>
				</positions>
				<positions axis="X" unit="mm">
					<commonPosition>-1.57</commonPosition>
				</positions>
				<positions axis="Y" unit="mm">
					<commonPosition>0.80</commonPosition>
				</positions>
				<positions axis="Z" unit="mm">
					<commonPosition>6.427</commonPosition>
				</positions>
				<commonCountingTime unit="seconds">0.440</commonCountingTime>
				<counts unit="counts">3 5 5 5 1 0 4 3 2 4 5 4 3 5 2 4 2 6 4 4 4 3 3 1 4 5 2 0 1 2 6 3 5 3 5 3 4 5 2 2 7 4 2 2 2 0 3 3 5 2 3 4 1 4 3 3 1 5 7 1 3 2 5 3 5 4 6 1 1 5 4 3 2 4 2 1 2 1 5 6 2 3 10 3 2 2 4 2 4 1 2 7 2 2 0 7 2 2 3 2 6 3 7 4 5 6 6 1 0 3 3 2 2 8 0 1 2 1 5 1 5 7 5 1 4 5 1 3 6 4 3 4 4 3 7 4 1 5 8 4 3 3 8 1 4 1 6 2 2 3 3 4 4 2 3 3 6 2 5 5 4 1 3 2 5 1 1 5 5 5 0 1 9 8 6 4 5 5 2 3 2 1 0 5 0 6 2 2 1 4 1 9 3 3 2 4 1 7 2 4 2 3 2 4 3 0 2 1 2 2 2 4 4 5 4 6 4 4 3 2 5 6 7 1 2 2 6 7 1 5 6 1 6 2 5 5 4 4 3 2 3 4 7 4 5 4 2 2 4 3 2 4 8 1 4 3 3 4 3 5 10 2 3 6 5 4 3 6 1 2 2 1 3 5 5 6 1 1 4 8 0 1 3 1 0 4 4 7 4 4 1 4 4 4 1 3 5 5 3 2 3 5 5 1 3 3 5 1 2 3 4 3 2 1 11 4 2 2 2 6 8 2 4 2 6 2 2 2 5 1 1 6 1 3 5 3 2 1 0 4 4 4 3 2 4 5 2 3 1 7 3 4 5 4 1 5 3 4 4 5</counts>
			</dataPoints>
		</scan>
		<scan appendNumber="0" mode="Continuous" scanAxis="Phi" status="Completed">
			<header>
				<startTimeStamp>2020-09-09T11:06:01+02:00</startTimeStamp>
				<endTimeStamp>2020-09-09T11:09:03+02:00</endTimeStamp>
				<author>
					<name>User</name>
				</author>
				<source>
					<applicationSoftware version="6.1">Data Collector</applicationSoftware>
					<instrumentControlSoftware version="2.2F 20161117">XPERT-PRO</instrumentControlSoftware>
					<instrumentID>0000000011073629</instrumentID>
				</source>
			</header>
			<dataPoints>
				<positions axis="2Theta" unit="deg">
					<commonPosition>29.8800</commonPosition>
				</positions>
				<positions axis="Omega" unit="deg">
					<commonPosition>14.9400</commonPosition>
				</positions>
				<positions axis="Phi" unit="deg">
					<startPosition>0.50</startPosition>
					<endPosition>359.50</endPosition>
				</positions>
				<positions axis="Chi" unit="deg">
					<commonPosition>12.00</commonPosition>
				</positions>
				<positions axis="X" unit="mm">
					<commonPosition>-1.57</commonPosition>
				</positions>
				<positions axis="Y" unit="mm">
					<commonPosition>0.80</commonPosition>
				</positions>
				<positions axis="Z" unit="mm">
					<commonPosition>6.427</commonPosition>
				</positions>
				<commonCountingTime unit="seconds">0.440</commonCountingTime>
				<counts unit="counts">6 2 5 6 3 2 6 2 2 5 6 3 1 3 3 7 3 3 2 1 4 3 3 5 3 3 4 3 1 2 2 5 3 3 6 2 2 1 6 5 2 6 3 2 1 6 1 1 7 3 4 5 6 2 2 2 4 4 3 2 2 1 2 3 3 6 1 3 4 4 3 5 3 4 0 5 6 4 4 11 1 2 4 5 1 5 1 6 3 6 6 7 4 2 4 5 3 5 4 5 2 4 1 5 1 2 4 2 2 7 7 2 3 1 5 2 4 4 3 7 1 4 7 2 4 5 5 3 5 3 4 1 2 4 5 2 6 6 4 0 6 6 6 3 2 9 6 4 2 1 5 3 3 2 3 2 7 5 3 0 5 2 4 6 6 1 5 2 5 4 7 6 5 1 4 1 4 7 2 1 5 2 2 5 5 5 7 5 0 3 5 3 0 1 5 7 5 4 2 0 3 2 5 2 2 7 4 3 3 5 5 0 0 4 1 2 0 6 3 4 1 5 2 1 3 4 2 1 3 4 5 1 2 2 5 3 2 3 1 5 2 4 1 4 3 7 1 3 6 3 6 4 6 0 3 5 0 3 0 4 5 4 2 3 1 5 2 11 4 3 4 3 4 4 3 6 2 1 3 1 3 4 2 5 6 3 6 2 4 8 2 2 0 4 1 3 3 4 4 8 4 2 8 2 3 3 6 0 1 1 1 2 5 2 4 4 1 2 1 2 1 3 4 3 3 4 5 1 4 6 7 4 4 4 3 2 4 2 6 4 2 1 1 5 5 2 3 3 0 3 7 3 0 2 6 3 6 1 5 2</counts>
			</dataPoints>
		</scan>
		<scan appendNumber="0" mode="Continuous" scanAxis="Phi" status="Completed">
			<header>
				<startTimeStamp>2020-09-09T11:09:14+02:00</startTimeStamp>
				<endTimeStamp>2020-09-09T11:12:16+02:00</endTimeStamp>
				<author>
					<name>User</name>
				</author>
				<source>
					<applicationSoftware version="6.1">Data Collector</applicationSoftware>
					<instrumentControlSoftware version="2.2F 20161117">XPERT-PRO</instrumentControlSoftware>
					<instrumentID>0000000011073629</instrumentID>
				</source>
			</header>
			<dataPoints>
				<positions axis="2Theta" unit="deg">
					<commonPosition>29.8800</commonPosition>
				</positions>
				<positions axis="Omega" unit="deg">
					<commonPosition>14.9400</commonPosition>
				</positions>
				<positions axis="Phi" unit="deg">
					<startPosition>0.50</startPosition>
					<endPosition>359.50</endPosition>
				</positions>
				<positions axis="Chi" unit="deg">
					<commonPosition>14.00</commonPosition>
				</positions>
				<positions axis="X" unit="mm">
					<commonPosition>-1.57</commonPosition>
				</positions>
				<positions axis="Y" unit="mm">
					<commonPosition>0.80</commonPosition>
				</positions>
				<positions axis="Z" unit="mm">
					<commonPosition>6.427</commonPosition>
				</positions>
				<commonCountingTime unit="seconds">0.440</commonCountingTime>
				<counts unit="counts">1 2 3 3 5 2 0 3 0 5 3 4 7 5 4 4 3 4 0 2 6 2 6 4 1 4 3 3 4 4 4 3 1 5 3 3 1 3 1 1 4 5 4 4 2 2 4 2 6 2 7 5 3 4 5 2 2 1 1 4 4 0 4 2 4 6 5 1 3 3 4 2 0 8 2 3 7 4 3 2 2 6 1 1 2 5 4 3 6 6 4 5 2 3 0 1 5 7 1 5 4 0 4 6 2 3 6 5 1 2 2 1 7 1 2 1 5 4 2 0 2 3 4 4 0 4 1 6 1 2 1 4 5 2 2 2 4 4 3 5 4 2 3 4 4 3 2 8 5 8 1 4 3 1 2 4 5 2 4 3 2 2 6 5 6 4 3 1 2 4 0 5 4 2 3 3 4 4 1 5 2 2 6 3 1 2 1 1 3 6 5 3 1 0 7 3 4 1 1 4 2 5 5 0 2 0 5 3 2 5 1 2 0 6 4 4 4 3 3 1 2 5 5 1 5 2 7 2 4 6 4 4 4 4 1 3 4 1 1 5 4 4 2 2 4 2 0 1 5 0 6 5 3 2 1 4 3 2 2 5 9 4 0 5 3 7 1 1 2 3 1 4 2 2 5 1 2 1 3 1 3 2 0 4 1 2 1 1 3 2 1 1 4 3 2 2 4 1 2 5 6 1 4 1 4 5 3 1 0 2 5 1 7 4 5 1 5 1 1 2 2 5 1 3 2 3 6 1 0 6 5 6 6 3 1 5 1 6 0 4 3 3 10 5 5 5 3 1 4 5 5 5 1 3 3 2 4 6 10 2</counts>
			</dataPoints>
		</scan>
		<scan appendNumber="0" mode="Continuous" scanAxis="Phi" status="Completed">
			<header>
				<startTimeStamp>2020-09-09T11:12:27+02:00</startTimeStamp>
				<endTimeStamp>2020-09-09T11:15:29+02:00</endTimeStamp>
				<author>
					<name>User</name>
				</author>
				<source>
					<applicationSoftware version="6.1">Data Collector</applicationSoftware>
					<instrumentControlSoftware version="2.2F 20161117">XPERT-PRO</instrumentControlSoftware>
					<instrumentID>0000000011073629</instrumentID>
				</source>
			</header>
			<dataPoints>
				<positions axis="2Theta" unit="deg">
					<commonPosition>29.8800</commonPosition>
				</positions>
				<positions axis="Omega" unit="deg">
					<commonPosition>14.9400</commonPosition>
				</positions>
				<positions axis="Phi" unit="deg">
					<startPosition>0.50</startPosition>
					<endPosition>359.50</endPosition>
				</positions>
				<positions axis="Chi" unit="deg">
					<commonPosition>16.00</commonPosition>
				</positions>
				<positions axis="X" unit="mm">
					<commonPosition>-1.57</commonPosition>
				</positions>
				<positions axis="Y" unit="mm">
					<commonPosition>0.80</commonPosition>
				</positions>
				<positions axis="Z" unit="mm">
					<commonPosition>6.427</commonPosition>
				</positions>
				<commonCountingTime unit="seconds">0.440</commonCountingTime>
				<counts unit="counts">1 2 4 5 2 1 1 3 5 3 1 2 1 3 1 4 2 1 6 5 3 2 3 5 1 5 4 1 3 4 4 0 1 4 1 5 0 6 7 4 1 1 6 3 4 2 3 2 3 4 1 3 4 1 3 4 5 3 5 0 0 5 5 5 2 1 1 1 4 4 4 1 3 4 1 7 3 3 8 3 2 3 1 2 4 5 3 1 6 7 4 4 4 4 6 5 4 5 2 4 2 8 5 1 1 5 7 2 6 3 1 1 2 0 4 5 4 4 1 4 1 4 0 0 4 4 5 4 5 4 7 3 2 2 5 6 1 6 0 6 3 3 5 2 1 4 4 5 1 3 1 5 6 5 2 5 6 3 4 5 7 1 5 2 5 2 4 0 10 4 4 1 5 2 2 5 6 5 2 1 4 1 2 2 4 6 2 6 4 3 1 0 3 3 8 4 2 3 5 1 1 1 2 1 6 3 5 4 4 5 5 1 2 5 3 1 5 6 2 4 2 0 5 6 2 3 2 2 1 7 2 1 0 5 2 2 1 5 2 4 4 3 3 2 3 3 1 8 3 4 2 5 5 1 2 1 5 3 6 1 3 7 3 5 3 1 1 4 2 1 2 4 6 1 2 4 0 7 3 2 1 6 2 0 2 1 0 5 4 3 6 7 2 4 0 6 1 3 5 1 3 0 2 3 2 5 1 3 4 1 5 2 4 4 2 8 7 4 3 3 4 2 5 4 4 0 1 5 3 4 2 3 3 3 5 4 4 1 3 1 3 7 2 1 1 4 1 3 2 0 0 5 2 5 8 4 1 1 1 3</counts>
			</dataPoints>
		</scan>
		<scan appendNumber="0" mode="Continuous" scanAxis="Phi" status="Completed">
			<header>
				<startTimeStamp>2020-09-09T11:15:39+02:00</startTimeStamp>
				<endTimeStamp>2020-09-09T11:18:41+02:00</endTimeStamp>
				<author>
					<name>User</name>
				</author>
				<source>
					<applicationSoftware version="6.1">Data Collector</applicationSoftware>
					<instrumentControlSoftware version="2.2F 20161117">XPERT-PRO</instrumentControlSoftware>
					<instrumentID>0000000011073629</instrumentID>
				</source>
			</header>
			<dataPoints>
				<positions axis="2Theta" unit="deg">
					<commonPosition>29.8800</commonPosition>
				</positions>
				<positions axis="Omega" unit="deg">
					<commonPosition>14.9400</commonPosition>
				</positions>
				<positions axis="Phi" unit="deg">
					<startPosition>0.50</startPosition>
					<endPosition>359.50</endPosition>
				</positions>
				<positions axis="Chi" unit="deg">
					<commonPosition>18.00</commonPosition>
				</positions>
				<positions axis="X" unit="mm">
					<commonPosition>-1.57</commonPosition>
				</positions>
				<positions axis="Y" unit="mm">
					<commonPosition>0.80</commonPosition>
				</positions>
				<positions axis="Z" unit="mm">
					<commonPosition>6.427</commonPosition>
				</positions>
				<commonCountingTime unit="seconds">0.440</commonCountingTime>
				<counts unit="counts">0 2 3 1 2 2 2 5 4 5 0 7 1 1 3 1 1 1 2 3 4 2 1 4 1 0 1 3 3 6 0 5 2 1 3 0 6 2 2 1 3 1 2 4 3 2 6 6 5 3 2 4 1 1 4 3 3 9 2 6 3 5 2 5 4 4 4 7 3 3 2 3 3 5 2 4 9 0 4 2 5 4 7 6 3 7 5 7 7 3 2 3 11 4 7 3 4 6 5 0 3 4 3 5 2 3 1 4 2 4 5 8 4 5 2 5 3 1 4 5 3 5 4 1 3 6 1 4 7 1 2 4 2 1 1 4 1 2 2 3 3 2 4 3 4 4 1 0 2 6 4 4 4 1 2 4 1 7 4 7 3 2 6 3 4 3 1 1 3 6 4 2 4 3 3 2 2 7 7 6 2 1 2 4 4 6 6 1 3 5 2 1 5 1 0 3 4 0 2 5 4 3 2 3 5 1 1 3 5 1 1 4 0 4 1 2 1 4 3 1 4 5 3 5 5 4 3 7 4 4 6 3 1 3 3 7 1 6 2 4 1 0 4 1 1 2 4 2 7 1 2 6 3 4 2 5 4 4 5 4 4 2 6 1 4 3 4 5 4 5 5 3 2 4 2 0 2 2 0 1 1 1 3 1 4 3 3 4 1 4 1 1 5 4 1 2 1 4 2 4 4 4 5 1 1 2 3 2 6 5 3 3 2 4 6 1 2 2 1 2 1 5 2 4 1 4 4 1 5 4 4 1 5 2 4 4 1 7 7 4 4 0 6 1 4 5 1 4 4 1 2 2 2 3 4 4 6 1 4 1</counts>
			</dataPoints>
		</scan>
		<scan appendNumber="0" mode="Continuous" scanAxis="Phi" status="Completed">
			<header>
				<startTimeStamp>2020-09-09T11:18:52+02:00</startTimeStamp>
				<endTimeStamp>2020-09-09T11:21:54+02:00</endTimeStamp>
				<author>
					<name>User</name>
				</author>
				<source>
					<applicationSoftware version="6.1">Data Collector</applicationSoftware>
					<instrumentControlSoftware version="2.2F 20161117">XPERT-PRO</instrumentControlSoftware>
					<instrumentID>0000000011073629</instrumentID>
				</source>
			</header>
			<dataPoints>
				<positions axis="2Theta" unit="deg">
					<commonPosition>29.8800</commonPosition>
				</positions>
				<positions axis="Omega" unit="deg">
					<commonPosition>14.9400</commonPosition>
				</positions>
				<positions axis="Phi" unit="deg">
					<startPosition>0.50</startPosition>
					<endPosition>359.50</endPosition>
				</positions>
				<positions axis="Chi" unit="deg">
					<commonPosition>20.00</commonPosition>
				</positions>
				<positions axis="X" unit="mm">
					<commonPosition>-1.57</commonPosition>
				</positions>
				<positions axis="Y" unit="mm">
					<commonPosition>0.80</commonPosition>
				</positions>
				<positions axis="Z" unit="mm">
					<commonPosition>6.427</commonPosition>
				</positions>
				<commonCountingTime unit="seconds">0.440</commonCountingTime>
				<counts unit="counts">3 9 1 1 1 1 4 3 3 4 3 4 1 6 1 0 0 1 1 4 2 1 7 3 5 2 2 2 0 2 4 2 5 3 5 2 3 1 1 2 3 0 4 4 7 5 5 1 1 3 0 8 1 2 2 1 3 1 2 3 3 4 3 2 3 4 3 5 4 2 6 5 2 4 6 5 2 7 4 7 1 4 4 10 1 7 9 5 8 1 5 3 3 2 6 2 1 1 6 1 2 2 3 4 1 2 3 5 5 4 0 1 3 3 3 4 2 6 2 3 0 4 2 4 2 4 2 3 3 5 0 3 0 2 2 1 3 4 1 4 8 2 0 0 4 4 4 3 4 2 1 4 6 2 3 5 7 1 3 5 2 4 1 4 6 2 3 4 4 3 2 4 7 1 3 4 3 8 3 4 5 1 2 5 3 4 4 3 4 3 4 1 8 2 2 1 1 2 1 4 2 2 5 4 1 4 2 5 4 3 4 5 4 3 4 4 5 4 1 0 2 2 4 2 2 4 4 2 6 4 3 1 1 4 1 6 0 3 3 1 5 3 4 9 4 4 1 4 1 0 7 2 4 2 7 4 3 5 1 4 1 6 2 6 2 3 2 5 1 4 4 1 1 7 2 4 6 4 4 3 5 2 6 3 5 7 7 1 0 4 4 1 3 4 2 1 3 0 1 1 6 4 2 4 0 1 4 6 4 3 1 4 2 1 1 3 4 5 4 6 1 4 4 1 0 7 2 4 6 2 1 7 6 4 4 1 5 5 1 2 1 5 0 1 3 4 1 7 3 5 4 2 4 1 3 4 3 2 5 1</counts>
			</dataPoints>
		</scan>
		<scan appendNumber="0" mode="Continuous" scanAxis="Phi" status="Completed">
			<header>
				<startTimeStamp>2020-09-09T11:22:05+02:00</startTimeStamp>
				<endTimeStamp>2020-09-09T11:25:07+02:00</endTimeStamp>
				<author>
					<name>User</name>
				</author>
				<source>
					<applicationSoftware version="6.1">Data Collector</applicationSoftware>
					<instrumentControlSoftware version="2.2F 20161117">XPERT-PRO</instrumentControlSoftware>
					<instrumentID>0000000011073629</instrumentID>
				</source>
			</header>
			<dataPoints>
				<positions axis="2Theta" unit="deg">
					<commonPosition>29.8800</commonPosition>
				</positions>
				<positions axis="Omega" unit="deg">
					<commonPosition>14.9400</commonPosition>
				</positions>
				<positions axis="Phi" unit="deg">
					<startPosition>0.50</startPosition>
					<endPosition>359.50</endPosition>
				</positions>
				<positions axis="Chi" unit="deg">
					<commonPosition>22.00</commonPosition>
				</positions>
				<positions axis="X" unit="mm">
					<commonPosition>-1.57</commonPosition>
				</positions>
				<positions axis="Y" unit="mm">
					<commonPosition>0.80</commonPosition>
				</positions>
				<positions axis="Z" unit="mm">
					<commonPosition>6.427</commonPosition>
				</positions>
				<commonCountingTime unit="seconds">0.440</commonCountingTime>
				<counts unit="counts">4 4 1 4 2 2 2 1 2 3 1 5 6 3 5 1 4 3 4 3 4 4 7 5 2 2 1 4 3 3 6 6 1 1 1 4 2 6 2 4 0 1 2 5 3 0 4 5 1 0 1 1 3 5 1 0 1 2 4 2 5 5 9 5 2 7 3 6 4 2 7 7 4 1 5 1 4 1 5 5 7 3 3 2 5 5 4 4 2 6 3 1 4 3 2 2 4 5 0 1 3 5 1 2 3 3 4 4 7 1 4 2 3 4 4 4 1 1 3 6 4 2 3 2 1 8 4 4 0 1 1 3 2 3 1 4 4 1 4 3 0 5 1 2 2 1 3 1 4 2 6 4 1 1 3 2 1 4 4 3 4 2 5 1 1 1 8 2 8 2 7 9 2 2 5 5 2 2 1 1 4 2 2 6 3 3 1 2 9 0 3 6 1 4 6 1 1 2 5 4 5 2 2 2 3 2 1 2 4 2 2 2 1 3 1 2 4 4 2 2 2 4 2 1 1 2 1 4 3 5 3 4 6 4 4 4 2 2 2 2 1 5 2 8 6 0 3 3 2 1 4 4 2 4 0 1 4 2 3 1 2 3 4 6 4 1 1 0 6 2 1 4 2 2 5 3 5 3 1 3 2 2 6 1 1 6 0 4 1 0 4 1 5 1 6 5 6 1 2 4 1 1 2 0 3 1 3 2 1 3 0 3 1 6 4 5 2 5 5 3 2 1 1 4 1 3 0 4 4 6 3 2 5 4 0 7 1 7 3 7 2 8 2 3 2 2 5 4 2 3 1 1 7 2 3 2 3 1 5 1</counts>
			</dataPoints>
		</scan>
		<scan appendNumber="0" mode="Continuous" scanAxis="Phi" status="Completed">
			<header>
				<startTimeStamp>2020-09-09T11:25:18+02:00</startTimeStamp>
				<endTimeStamp>2020-09-09T11:28:20+02:00</endTimeStamp>
				<author>
					<name>User</name>
				</author>
				<source>
					<applicationSoftware version="6.1">Data Collector</applicationSoftware>
					<instrumentControlSoftware version="2.2F 20161117">XPERT-PRO</instrumentControlSoftware>
					<instrumentID>0000000011073629</instrumentID>
				</source>
			</header>
			<dataPoints>
				<positions axis="2Theta" unit="deg">
					<commonPosition>29.8800</commonPosition>
				</positions>
				<positions axis="Omega" unit="deg">
					<commonPosition>14.9400</commonPosition>
				</positions>
				<positions axis="Phi" unit="deg">
					<startPosition>0.50</startPosition>
					<endPosition>359.50</endPosition>
				</positions>
				<positions axis="Chi" unit="deg">
					<commonPosition>24.00</commonPosition>
				</positions>
				<positions axis="X" unit="mm">
					<commonPosition>-1.57</commonPosition>
				</positions>
				<positions axis="Y" unit="mm">
					<commonPosition>0.80</commonPosition>
				</positions>
				<positions axis="Z" unit="mm">
					<commonPosition>6.427</commonPosition>
				</positions>
				<commonCountingTime unit="seconds">0.440</commonCountingTime>
				<counts unit="counts">4 1 5 5 2 0 2 3 1 2 1 5 5 7 4 2 1 6 4 3 2 1 3 3 4 3 1 4 5 4 1 3 4 4 4 2 7 6 0 2 2 2 1 2 1 1 4 1 4 5 2 1 7 1 4 1 3 3 1 3 3 3 5 6 4 4 3 3 5 1 3 3 1 1 1 5 2 1 7 3 4 7 1 15 9 3 5 2 4 0 4 4 5 3 1 5 1 6 2 4 1 0 4 1 2 1 1 5 7 6 2 1 2 2 4 7 2 2 5 3 6 7 4 1 2 1 4 5 2 2 2 1 1 2 2 2 5 4 0 6 4 0 1 3 2 3 2 4 5 5 5 3 1 3 4 4 2 2 1 2 4 1 1 1 3 7 0 4 4 1 4 6 5 2 2 3 1 3 1 2 5 3 3 4 2 4 4 4 4 4 1 5 1 4 5 1 2 2 0 2 2 1 1 4 3 1 4 1 1 2 5 2 5 3 0 5 4 10 3 1 1 0 5 6 2 0 7 1 5 4 2 1 1 7 3 2 2 4 6 2 3 5 5 5 2 2 4 3 2 0 4 6 2 7 3 1 3 2 5 5 4 0 6 6 4 2 3 4 1 3 3 2 1 1 3 2 1 4 2 4 0 3 8 3 1 5 2 2 5 1 2 4 2 1 3 4 0 0 5 3 2 1 2 2 2 3 3 3 0 3 2 1 5 5 6 3 2 4 2 4 6 4 4 6 4 1 1 3 3 7 4 7 5 5 4 4 1 3 6 1 1 4 5 5 3 1 1 3 5 4 4 4 2 1 0 0 4 6 3 1</counts>
			</dataPoints>
		</scan>
		<scan appendNumber="0" mode="Continuous" scanAxis="Phi" status="Completed">
			<header>
				<startTimeStamp>2020-09-09T11:28:31+02:00</startTimeStamp>
				<endTimeStamp>2020-09-09T11:31:33+02:00</endTimeStamp>
				<author>
					<name>User</name>
				</author>
				<source>
					<applicationSoftware version="6.1">Data Collector</applicationSoftware>
					<instrumentControlSoftware version="2.2F 20161117">XPERT-PRO</instrumentControlSoftware>
					<instrumentID>0000000011073629</instrumentID>
				</source>
			</header>
			<dataPoints>
				<positions axis="2Theta" unit="deg">
					<commonPosition>29.8800</commonPosition>
				</positions>
				<positions axis="Omega" unit="deg">
					<commonPosition>14.9400</commonPosition>
				</positions>
				<positions axis="Phi" unit="deg">
					<startPosition>0.50</startPosition>
					<endPosition>359.50</endPosition>
				</positions>
				<positions axis="Chi" unit="deg">
					<commonPosition>26.00</commonPosition>
				</positions>
				<positions axis="X" unit="mm">
					<commonPosition>-1.57</commonPosition>
				</positions>
				<positions axis="Y" unit="mm">
					<commonPosition>0.80</commonPosition>
				</positions>
				<positions axis="Z" unit="mm">
					<commonPosition>6.427</commonPosition>
				</positions>
				<commonCountingTime unit="seconds">0.440</commonCountingTime>
				<counts unit="counts">4 3 1 3 0 1 2 1 6 2 1 6 4 2 1 5 3 4 3 3 4 2 3 2 6 4 4 2 1 5 2 4 6 3 2 4 1 3 0 1 0 1 6 3 2 3 4 3 7 7 1 4 1 3 1 1 2 1 4 1 1 2 3 4 3 5 5 0 5 4 1 0 3 2 5 1 9 3 1 4 1 1 3 1 8 5 4 4 5 1 5 4 7 2 2 4 4 3 2 3 6 1 2 5 1 8 2 3 1 1 5 3 5 0 3 0 1 3 3 4 6 4 1 4 4 6 1 3 5 6 4 5 3 1 3 0 2 5 4 3 3 4 4 5 6 3 2 0 4 1 1 4 3 2 1 4 4 5 5 5 0 2 4 4 1 2 3 3 3 3 1 4 5 1 1 2 4 2 2 1 2 1 4 2 2 6 4 2 1 1 3 4 7 3 1 3 0 2 1 5 3 1 1 1 2 4 3 2 3 4 3 4 4 2 0 7 3 1 1 0 5 5 0 1 3 1 4 4 0 3 2 4 1 5 5 4 4 2 4 4 6 3 0 5 6 1 5 2 3 2 2 3 3 2 2 4 1 6 6 1 1 3 5 2 3 2 3 1 5 6 9 3 4 2 3 3 3 1 1 3 3 3 2 1 0 2 5 2 4 4 5 3 2 1 1 4 4 5 2 2 4 5 4 2 4 1 3 1 5 2 3 2 2 3 4 3 1 3 0 2 2 2 2 3 4 8 2 1 4 3 3 4 2 3 4 4 2 3 5 0 1 5 1 3 1 5 4 1 2 2 2 1 6 5 4 3 1 1 3 0</counts>
			</dataPoints>
		</scan>
		<scan appendNumber="0" mode="Continuous" scanAxis="Phi" status="Completed">
			<header>
				<startTimeStamp>2020-09-09T11:31:44+02:00</startTimeStamp>
				<endTimeStamp>2020-09-09T11:34:46+02:00</endTimeStamp>
				<author>
					<name>User</name>
				</author>
				<source>
					<applicationSoftware version="6.1">Data Collector</applicationSoftware>
					<instrumentControlSoftware version="2.2F 20161117">XPERT-PRO</instrumentControlSoftware>
					<instrumentID>0000000011073629</instrumentID>
				</source>
			</header>
			<dataPoints>
				<positions axis="2Theta" unit="deg">
					<commonPosition>29.8800</commonPosition>
				</positions>
				<positions axis="Omega" unit="deg">
					<commonPosition>14.9400</commonPosition>
				</positions>
				<positions axis="Phi" unit="deg">
					<startPosition>0.50</startPosition>
					<endPosition>359.50</endPosition>
				</positions>
				<positions axis="Chi" unit="deg">
					<commonPosition>28.00</commonPosition>
				</positions>
				<positions axis="X" unit="mm">
					<commonPosition>-1.57</commonPosition>
				</positions>
				<positions axis="Y" unit="mm">
					<commonPosition>0.80</commonPosition>
				</positions>
				<positions axis="Z" unit="mm">
					<commonPosition>6.427</commonPosition>
				</positions>
				<commonCountingTime unit="seconds">0.440</commonCountingTime>
				<counts unit="counts">4 2 3 2 1 0 1 3 2 2 4 5 2 2 1 0 4 1 3 4 5 3 1 1 1 7 3 3 2 2 2 4 3 4 5 2 2 5 1 5 4 4 1 3 1 4 1 2 1 2 2 2 7 2 4 6 1 1 3 4 9 4 5 4 2 5 4 4 4 7 3 6 1 3 4 1 6 2 3 6 3 5 3 8 2 4 4 2 4 1 0 2 0 3 3 4 2 0 1 1 2 0 6 3 5 4 1 4 2 4 0 3 5 3 3 3 6 3 2 1 4 2 1 4 8 3 1 2 0 1 6 2 1 3 4 4 5 2 1 3 4 3 3 4 1 7 4 3 4 3 1 2 1 1 5 6 1 3 1 3 5 4 2 1 0 3 3 3 3 7 5 5 4 4 1 1 2 4 2 0 0 1 1 5 4 2 1 2 0 4 4 4 7 0 3 1 1 5 1 1 3 4 6 7 1 1 4 4 1 4 1 2 5 3 1 3 2 1 5 4 6 0 1 5 2 4 2 4 6 2 1 5 4 3 2 1 4 3 2 4 1 6 0 4 1 0 0 4 3 3 4 6 6 0 0 4 0 6 2 2 5 2 1 8 2 1 2 4 3 1 3 4 3 2 2 0 3 2 5 1 1 4 2 3 2 6 2 3 1 4 1 1 5 2 4 4 3 1 0 5 0 2 1 7 2 0 5 4 4 1 1 1 4 3 1 2 1 3 4 7 3 1 3 5 1 5 2 6 3 2 5 5 0 5 1 3 4 5 6 1 3 5 4 2 2 3 0 5 1 4 2 3 2 1 2 1 5 1 1 5</counts>
			</dataPoints>
		</scan>
		<scan appendNumber="0" mode="Continuous" scanAxis="Phi" status="Completed">
			<header>
				<startTimeStamp>2020-09-09T11:34:57+02:00</startTimeStamp>
				<endTimeStamp>2020-09-09T11:37:59+02:00</endTimeStamp>
				<author>
					<name>User</name>
				</author>
				<source>
					<applicationSoftware version="6.1">Data Collector</applicationSoftware>
					<instrumentControlSoftware version="2.2F 20161117">XPERT-PRO</instrumentControlSoftware>
					<instrumentID>0000000011073629</instrumentID>
				</source>
			</header>
			<dataPoints>
				<positions axis="2Theta" unit="deg">
					<commonPosition>29.8800</commonPosition>
				</positions>
				<positions axis="Omega" unit="deg">
					<commonPosition>14.9400</commonPosition>
				</positions>
				<positions axis="Phi" unit="deg">
					<startPosition>0.50</startPosition>
					<endPosition>359.50</endPosition>
				</positions>
				<positions axis="Chi" unit="deg">
					<commonPosition>30.00</commonPosition>
				</positions>
				<positions axis="X" unit="mm">
					<commonPosition>-1.57</commonPosition>
				</positions>
				<positions axis="Y" unit="mm">
					<commonPosition>0.80</commonPosition>
				</positions>
				<positions axis="Z" unit="mm">
					<commonPosition>6.427</commonPosition>
				</positions>
				<commonCountingTime unit="seconds">0.440</commonCountingTime>
				<counts unit="counts">6 3 4 0 1 2 3 2 2 5 4 6 6 4 3 3 5 5 0 1 2 1 4 2 2 4 4 2 2 2 4 0 6 4 1 1 0 1 1 0 0 3 2 3 6 4 0 0 3 5 1 2 1 6 1 3 1 1 5 2 2 5 2 2 3 4 3 1 1 1 7 3 1 1 0 0 3 4 1 3 4 4 0 3 4 3 2 4 1 5 2 3 2 3 2 1 2 1 4 6 4 2 1 0 2 1 4 2 1 3 1 2 0 4 2 3 3 0 1 1 1 1 3 0 4 2 1 1 4 4 1 3 5 2 1 5 5 1 2 4 1 1 5 10 2 7 4 4 4 2 4 2 4 3 4 5 7 1 3 3 0 7 1 1 6 6 1 3 3 3 5 3 2 2 3 2 5 1 2 4 1 1 1 3 1 4 4 2 2 6 5 1 2 3 5 7 4 5 5 2 2 3 1 1 4 2 4 4 2 4 4 0 1 1 3 2 4 2 1 2 5 1 2 3 4 2 1 5 1 1 1 2 3 4 2 3 1 4 6 2 7 2 2 1 3 4 5 8 1 5 5 0 2 3 3 1 1 6 1 5 5 5 2 7 2 4 1 3 5 1 3 1 2 6 3 1 5 2 2 2 1 1 2 7 4 2 3 1 4 4 4 6 4 6 2 1 1 1 4 3 4 0 3 3 2 8 2 2 0 0 4 3 4 1 5 0 1 3 5 0 3 2 5 3 2 4 1 3 2 3 1 4 4 1 0 3 0 0 2 1 2 2 1 2 1 1 2 4 6 4 3 4 3 2 0 1 1 3 2 4</counts>
			</dataPoints>
		</scan>
		<scan appendNumber="0" mode="Continuous" scanAxis="Phi" status="Completed">
			<header>
				<startTimeStamp>2020-09-09T11:38:10+02:00</startTimeStamp>
				<endTimeStamp>2020-09-09T11:41:12+02:00</endTimeStamp>
				<author>
					<name>User</name>
				</author>
				<source>
					<applicationSoftware version="6.1">Data Collector</applicationSoftware>
					<instrumentControlSoftware version="2.2F 20161117">XPERT-PRO</instrumentControlSoftware>
					<instrumentID>0000000011073629</instrumentID>
				</source>
			</header>
			<dataPoints>
				<positions axis="2Theta" unit="deg">
					<commonPosition>29.8800</commonPosition>
				</positions>
				<positions axis="Omega" unit="deg">
					<commonPosition>14.9400</commonPosition>
				</positions>
				<positions axis="Phi" unit="deg">
					<startPosition>0.50</startPosition>
					<endPosition>359.50</endPosition>
				</positions>
				<positions axis="Chi" unit="deg">
					<commonPosition>32.00</commonPosition>
				</positions>
				<positions axis="X" unit="mm">
					<commonPosition>-1.57</commonPosition>
				</positions>
				<positions axis="Y" unit="mm">
					<commonPosition>0.80</commonPosition>
				</positions>
				<positions axis="Z" unit="mm">
					<commonPosition>6.427</commonPosition>
				</positions>
				<commonCountingTime unit="seconds">0.440</commonCountingTime>
				<counts unit="counts">4 1 3 3 8 2 1 2 7 1 4 3 2 5 2 1 1 1 4 3 1 1 1 4 0 4 1 2 4 6 2 4 5 6 3 2 2 6 4 3 2 4 1 2 3 3 2 2 1 6 0 0 3 3 2 7 2 1 2 3 3 0 4 3 4 5 4 8 4 1 1 5 2 1 5 1 2 1 0 5 4 3 4 2 4 3 4 4 3 1 6 4 1 4 3 4 1 4 2 1 3 2 2 7 1 1 6 0 2 2 2 3 1 1 4 1 2 1 0 2 5 1 3 3 5 4 3 5 3 6 3 4 7 5 2 1 6 4 2 0 3 1 5 0 2 1 4 5 4 2 5 5 5 4 5 2 3 4 3 2 4 4 3 1 2 3 1 0 1 1 4 2 3 3 1 8 0 0 0 1 2 3 6 4 5 1 1 5 2 0 1 4 4 2 1 3 3 4 0 1 2 2 1 1 2 3 0 3 0 1 1 2 0 2 3 1 7 4 0 1 2 2 1 2 5 3 4 2 4 3 2 3 1 0 2 3 4 1 4 6 3 2 4 3 5 2 3 1 5 3 2 1 0 3 2 3 3 1 1 3 5 6 4 2 3 2 2 4 5 1 5 0 4 0 1 3 1 3 2 2 6 2 1 5 1 5 1 6 4 4 4 5 6 7 2 6 4 2 1 3 1 3 1 0 7 3 1 2 1 1 2 0 2 1 4 2 4 4 7 2 5 5 3 5 4 1 4 5 2 1 8 1 4 8 1 3 3 4 3 4 4 1 4 4 2 5 3 5 1 2 1 9 3 2 3 1 0 3 2 2</counts>
			</dataPoints>
		</scan>
		<scan appendNumber="0" mode="Continuous" scanAxis="Phi" status="Completed">
			<header>
				<startTimeStamp>2020-09-09T11:41:23+02:00</startTimeStamp>
				<endTimeStamp>2020-09-09T11:44:25+02:00</endTimeStamp>
				<author>
					<name>User</name>
				</author>
				<source>
					<applicationSoftware version="6.1">Data Collector</applicationSoftware>
[...]
					<commonPosition>6.427</commonPosition>
				</positions>
				<commonCountingTime unit="seconds">0.440</commonCountingTime>
				<counts unit="counts">3 0 5 1 4 4 2 6 0 3 3 2 4 2 1 3 3 2 4 3 2 4 0 1 3 8 1 2 5 1 1 3 5 1 1 3 3 4 1 2 2 8 1 1 1 3 2 4 1 1 2 1 3 1 0 1 3 2 3 5 1 2 5 1 1 0 2 4 3 4 5 1 1 4 4 4 5 2 3 1 3 4 6 2 1 3 1 3 4 1 2 1 0 1 5 4 1 2 3 4 4 3 2 2 0 3 1 3 1 1 4 0 1 1 3 3 4 2 3 2 1 2 3 1 2 5 1 1 3 1 1 1 5 1 3 0 1 3 2 4 2 0 4 2 1 2 1 0 1 4 4 2 2 2 1 2 3 2 2 2 2 4 2 2 3 3 2 0 2 1 1 3 1 2 0 1 3 4 1 1 1 1 3 4 2 2 7 2 1 2 2 3 1 1 3 1 2 3 4 2 1 1 6 3 1 2 2 2 1 2 0 2 1 2 0 2 3 4 5 5 7 1 1 4 5 2 0 0 1 2 4 1 2 0 2 6 0 4 2 1 2 2 4 0 2 1 2 5 4 2 1 4 4 3 3 0 1 1 3 1 1 0 4 1 2 2 2 4 1 2 2 2 0 1 4 6 2 1 2 0 0 0 3 5 1 4 2 0 0 3 1 4 4 1 0 1 3 1 1 0 1 2 1 2 0 0 2 0 5 2 5 2 3 5 1 0 0 6 0 4 0 1 5 4 1 2 0 1 1 4 2 2 1 5 0 3 2 3 1 1 4 2 2 2 3 0 1 0 3 2 3 2 1 4 0 1 5 1 2 2</counts>
			</dataPoints>
		</scan>
		<scan appendNumber="0" mode="Continuous" scanAxis="Phi" status="Completed">
			<header>
				<startTimeStamp>2020-09-09T12:45:41+02:00</startTimeStamp>
				<endTimeStamp>2020-09-09T12:48:43+02:00</endTimeStamp>
				<author>
					<name>User</name>
				</author>
				<source>
					<applicationSoftware version="6.1">Data Collector</applicationSoftware>
					<instrumentControlSoftware version="2.2F 20161117">XPERT-PRO</instrumentControlSoftware>
					<instrumentID>0000000011073629</instrumentID>
				</source>
			</header>
			<dataPoints>
				<positions axis="2Theta" unit="deg">
					<commonPosition>29.8800</commonPosition>
				</positions>
				<positions axis="Omega" unit="deg">
					<commonPosition>14.9400</commonPosition>
				</positions>
				<positions axis="Phi" unit="deg">
					<startPosition>0.50</startPosition>
					<endPosition>359.50</endPosition>
				</positions>
				<positions axis="Chi" unit="deg">
					<commonPosition>74.00</commonPosition>
				</positions>
				<positions axis="X" unit="mm">
					<commonPosition>-1.57</commonPosition>
				</positions>
				<positions axis="Y" unit="mm">
					<commonPosition>0.80</commonPosition>
				</positions>
				<positions axis="Z" unit="mm">
					<commonPosition>6.427</commonPosition>
				</positions>
				<commonCountingTime unit="seconds">0.440</commonCountingTime>
				<counts unit="counts">1 1 4 2 3 2 1 0 5 3 1 1 3 1 1 0 2 0 4 1 4 2 2 0 0 3 1 3 2 4 1 4 3 2 2 2 5 2 2 2 4 2 1 0 2 1 2 4 0 2 2 0 2 3 4 2 4 1 3 0 2 1 3 1 4 3 1 0 0 0 1 4 2 3 7 2 2 4 3 2 4 2 1 5 3 5 0 2 1 0 0 1 4 2 1 5 3 2 1 4 1 1 0 2 4 1 0 2 1 4 3 0 4 2 3 1 6 6 1 1 4 1 0 3 3 3 0 2 1 0 0 3 1 2 1 1 0 2 2 0 0 2 2 1 1 1 5 1 3 1 2 2 0 2 3 2 2 1 2 3 0 3 0 3 2 1 3 3 1 3 1 2 2 4 2 1 1 2 0 2 2 4 1 1 2 3 2 1 5 4 2 1 3 0 0 0 4 2 4 2 1 2 1 1 4 1 1 3 4 0 1 1 6 3 2 3 2 1 3 2 1 2 2 3 2 1 4 3 3 1 3 2 2 0 1 4 1 0 5 3 2 4 1 1 2 2 5 4 5 2 0 2 4 1 0 2 2 1 6 2 4 0 2 2 1 4 4 2 1 2 4 3 4 3 2 3 2 4 4 1 1 2 1 2 2 4 1 4 1 1 9 4 4 2 1 2 1 2 2 2 3 0 1 1 3 1 2 1 1 2 2 3 5 1 2 0 4 1 2 3 2 2 1 4 4 2 3 6 4 4 2 3 2 2 1 1 5 4 0 2 2 1 4 4 1 3 1 2 2 5 2 2 2 6 1 1 1 3 4 3</counts>
			</dataPoints>
		</scan>
		<scan appendNumber="0" mode="Continuous" scanAxis="Phi" status="Completed">
			<header>
				<startTimeStamp>2020-09-09T12:48:53+02:00</startTimeStamp>
				<endTimeStamp>2020-09-09T12:51:55+02:00</endTimeStamp>
				<author>
					<name>User</name>
				</author>
				<source>
					<applicationSoftware version="6.1">Data Collector</applicationSoftware>
					<instrumentControlSoftware version="2.2F 20161117">XPERT-PRO</instrumentControlSoftware>
					<instrumentID>0000000011073629</instrumentID>
				</source>
			</header>
			<dataPoints>
				<positions axis="2Theta" unit="deg">
					<commonPosition>29.8800</commonPosition>
				</positions>
				<positions axis="Omega" unit="deg">
					<commonPosition>14.9400</commonPosition>
				</positions>
				<positions axis="Phi" unit="deg">
					<startPosition>0.50</startPosition>
					<endPosition>359.50</endPosition>
				</positions>
				<positions axis="Chi" unit="deg">
					<commonPosition>76.00</commonPosition>
				</positions>
				<positions axis="X" unit="mm">
					<commonPosition>-1.57</commonPosition>
				</positions>
				<positions axis="Y" unit="mm">
					<commonPosition>0.80</commonPosition>
				</positions>
				<positions axis="Z" unit="mm">
					<commonPosition>6.427</commonPosition>
				</positions>
				<commonCountingTime unit="seconds">0.440</commonCountingTime>
				<counts unit="counts">2 2 2 5 5 2 1 4 1 0 4 1 2 1 1 2 1 2 3 0 1 2 2 4 0 1 1 5 5 3 1 2 4 1 2 1 3 3 2 3 4 1 3 1 1 3 2 2 6 5 1 1 4 1 0 0 0 4 1 2 1 4 3 7 2 0 3 0 2 4 1 2 2 5 1 2 5 2 1 3 5 0 0 1 3 1 2 2 2 1 0 1 1 4 1 0 4 2 1 2 2 1 1 4 1 1 1 0 1 2 2 0 4 2 2 1 3 6 3 3 3 4 4 2 4 4 3 1 1 3 2 5 1 2 0 2 1 2 4 1 3 3 1 2 2 1 2 1 1 2 1 1 2 4 4 1 0 2 3 4 4 2 0 0 2 1 2 1 2 4 1 2 0 4 3 1 3 3 2 3 2 3 1 1 1 1 1 2 3 0 1 4 3 3 3 2 4 1 2 4 0 2 2 3 3 0 1 1 2 2 2 2 4 1 5 2 4 2 1 2 1 2 4 1 2 5 2 3 5 2 1 1 2 3 4 1 5 1 1 3 6 2 1 3 0 4 0 1 1 5 1 1 1 3 1 2 6 1 3 1 3 1 2 0 5 1 1 0 2 3 4 2 3 3 0 4 2 4 1 5 1 1 2 3 5 1 8 0 4 4 3 0 3 2 3 0 2 0 2 1 3 4 1 4 2 3 1 3 3 5 0 0 4 2 1 2 2 3 0 3 3 3 2 1 2 0 1 2 1 3 3 3 2 1 5 1 4 2 1 4 2 5 1 0 3 2 3 2 4 1 2 3 1 3 2 1 2 2 3 4</counts>
			</dataPoints>
		</scan>
		<scan appendNumber="0" mode="Continuous" scanAxis="Phi" status="Completed">
			<header>
				<startTimeStamp>2020-09-09T12:52:06+02:00</startTimeStamp>
				<endTimeStamp>2020-09-09T12:55:08+02:00</endTimeStamp>
				<author>
					<name>User</name>
				</author>
				<source>
					<applicationSoftware version="6.1">Data Collector</applicationSoftware>
					<instrumentControlSoftware version="2.2F 20161117">XPERT-PRO</instrumentControlSoftware>
					<instrumentID>0000000011073629</instrumentID>
				</source>
			</header>
			<dataPoints>
				<positions axis="2Theta" unit="deg">
					<commonPosition>29.8800</commonPosition>
				</positions>
				<positions axis="Omega" unit="deg">
					<commonPosition>14.9400</commonPosition>
				</positions>
				<positions axis="Phi" unit="deg">
					<startPosition>0.50</startPosition>
					<endPosition>359.50</endPosition>
				</positions>
				<positions axis="Chi" unit="deg">
					<commonPosition>78.00</commonPosition>
				</positions>
				<positions axis="X" unit="mm">
					<commonPosition>-1.57</commonPosition>
				</positions>
				<positions axis="Y" unit="mm">
					<commonPosition>0.80</commonPosition>
				</positions>
				<positions axis="Z" unit="mm">
					<commonPosition>6.427</commonPosition>
				</positions>
				<commonCountingTime unit="seconds">0.440</commonCountingTime>
				<counts unit="counts">6 2 2 4 2 3 1 1 3 4 4 2 3 3 7 5 2 0 3 1 3 3 2 2 1 5 6 2 0 3 3 2 1 1 2 3 2 3 0 3 0 1 1 2 1 3 1 6 0 5 1 4 2 1 0 3 1 0 4 0 3 2 0 2 4 3 1 2 2 1 1 2 0 0 3 6 2 4 4 1 1 1 1 1 1 1 2 1 2 0 4 5 1 0 2 1 2 1 2 4 1 4 4 3 1 3 1 4 1 3 2 1 0 5 1 3 2 1 2 4 2 2 3 5 1 0 3 1 0 0 3 1 4 4 5 3 5 3 3 1 3 1 0 2 1 5 4 0 1 4 3 3 1 2 2 1 1 0 0 5 0 1 2 4 0 3 3 2 3 2 1 3 4 0 4 0 2 1 4 2 6 1 3 4 5 0 0 0 3 1 2 3 1 0 1 4 0 0 0 6 3 2 1 1 1 2 2 2 2 2 1 1 0 6 4 4 2 1 1 1 5 3 0 1 1 1 4 2 2 3 1 10 1 0 3 3 3 3 2 1 3 2 0 1 4 3 4 0 0 3 3 3 1 1 3 1 0 1 2 1 2 1 3 1 0 1 3 2 1 0 3 0 3 1 3 5 1 0 3 2 2 3 5 0 1 2 3 1 1 1 1 3 2 0 3 4 2 2 0 2 0 1 4 1 0 2 3 4 5 2 0 1 1 1 1 6 3 2 3 3 0 4 3 2 0 1 3 1 1 3 3 2 4 2 2 4 3 1 9 5 4 0 1 4 3 0 2 3 2 1 2 0 4 4 1 2 2 1 1 2</counts>
			</dataPoints>
		</scan>
		<scan appendNumber="0" mode="Continuous" scanAxis="Phi" status="Completed">
			<header>
				<startTimeStamp>2020-09-09T12:55:19+02:00</startTimeStamp>
				<endTimeStamp>2020-09-09T12:58:21+02:00</endTimeStamp>
				<author>
					<name>User</name>
				</author>
				<source>
					<applicationSoftware version="6.1">Data Collector</applicationSoftware>
					<instrumentControlSoftware version="2.2F 20161117">XPERT-PRO</instrumentControlSoftware>
					<instrumentID>0000000011073629</instrumentID>
				</source>
			</header>
			<dataPoints>
				<positions axis="2Theta" unit="deg">
					<commonPosition>29.8800</commonPosition>
				</positions>
				<positions axis="Omega" unit="deg">
					<commonPosition>14.9400</commonPosition>
				</positions>
				<positions axis="Phi" unit="deg">
					<startPosition>0.50</startPosition>
					<endPosition>359.50</endPosition>
				</positions>
				<positions axis="Chi" unit="deg">
					<commonPosition>80.00</commonPosition>
				</positions>
				<positions axis="X" unit="mm">
					<commonPosition>-1.57</commonPosition>
				</positions>
				<positions axis="Y" unit="mm">
					<commonPosition>0.80</commonPosition>
				</positions>
				<positions axis="Z" unit="mm">
					<commonPosition>6.427</commonPosition>
				</positions>
				<commonCountingTime unit="seconds">0.440</commonCountingTime>
				<counts unit="counts">1 2 1 3 0 2 0 0 1 1 1 0 2 2 2 5 1 2 2 2 6 5 1 0 4 4 1 4 1 5 5 4 5 3 3 1 4 0 3 2 4 2 1 5 4 1 4 2 4 2 7 5 1 0 1 1 2 0 4 0 3 1 1 1 5 2 4 1 1 1 1 2 1 2 1 4 1 3 1 1 0 2 3 2 0 1 2 2 2 1 2 0 5 4 1 0 1 2 4 2 2 2 1 5 1 2 0 1 1 3 4 1 1 0 3 0 3 1 0 2 2 3 0 1 1 1 0 2 1 3 1 1 2 2 1 0 1 2 2 1 2 1 4 2 2 1 5 1 1 5 5 3 1 1 2 1 2 4 1 2 4 0 2 1 2 1 1 2 0 3 3 4 1 2 2 1 2 4 2 3 1 2 4 2 1 3 0 2 1 3 0 4 3 2 1 1 2 1 2 0 2 4 1 4 0 2 5 0 4 4 2 4 0 1 0 1 4 4 1 0 3 1 1 1 0 0 1 0 0 2 2 4 2 1 3 1 1 2 1 1 1 1 2 1 3 0 1 3 6 0 3 2 4 1 0 5 2 1 0 3 1 3 0 0 1 0 1 4 3 2 5 2 4 0 2 0 1 0 3 3 1 1 3 1 3 4 2 3 4 2 0 4 4 4 2 2 0 2 1 2 1 1 3 3 4 4 4 4 0 1 3 0 3 3 2 2 2 1 2 3 2 1 3 2 2 3 0 3 1 1 3 0 1 5 3 1 2 1 0 5 2 2 0 4 4 2 3 2 2 0 4 4 0 1 1 2 2 4 0 4</counts>
			</dataPoints>
		</scan>
		<scan appendNumber="0" mode="Continuous" scanAxis="Phi" status="Completed">
			<header>
				<startTimeStamp>2020-09-09T12:58:32+02:00</startTimeStamp>
				<endTimeStamp>2020-09-09T13:01:34+02:00</endTimeStamp>
				<author>
					<name>User</name>
				</author>
				<source>
					<applicationSoftware version="6.1">Data Collector</applicationSoftware>
					<instrumentControlSoftware version="2.2F 20161117">XPERT-PRO</instrumentControlSoftware>
					<instrumentID>0000000011073629</instrumentID>
				</source>
			</header>
			<dataPoints>
				<positions axis="2Theta" unit="deg">
					<commonPosition>29.8800</commonPosition>
				</positions>
				<positions axis="Omega" unit="deg">
					<commonPosition>14.9400</commonPosition>
				</positions>
				<positions axis="Phi" unit="deg">
					<startPosition>0.50</startPosition>
					<endPosition>359.50</endPosition>
				</positions>
				<positions axis="Chi" unit="deg">
					<commonPosition>82.00</commonPosition>
				</positions>
				<positions axis="X" unit="mm">
					<commonPosition>-1.57</commonPosition>
				</positions>
				<positions axis="Y" unit="mm">
					<commonPosition>0.80</commonPosition>
				</positions>
				<positions axis="Z" unit="mm">
					<commonPosition>6.427</commonPosition>
				</positions>
				<commonCountingTime unit="seconds">0.440</commonCountingTime>
				<counts unit="counts">1 4 2 2 0 2 2 4 4 1 1 0 2 0 1 5 0 0 1 3 0 1 1 2 1 4 2 1 1 1 1 4 3 2 0 5 1 2 1 4 2 4 2 2 4 3 2 4 1 4 0 1 1 4 3 3 1 2 1 2 4 0 1 0 1 0 1 1 1 1 1 2 7 3 2 2 3 1 1 1 1 1 2 1 1 1 2 2 1 2 4 2 0 0 3 2 5 1 2 0 0 1 0 2 2 4 2 1 3 0 10 4 2 2 3 2 2 2 5 0 1 2 3 3 0 3 2 2 1 1 1 4 1 4 1 0 4 4 4 2 1 1 1 3 4 0 2 3 2 0 1 1 2 1 1 1 2 2 5 1 1 3 4 3 1 2 4 1 1 4 3 1 2 1 3 1 3 2 5 4 2 2 1 2 1 0 1 2 1 2 3 2 2 1 4 1 0 1 5 2 2 1 1 0 4 4 0 5 6 2 0 3 1 0 1 3 0 3 0 2 4 3 1 3 2 1 0 2 1 4 4 1 0 2 5 2 1 2 1 2 4 1 1 1 1 4 5 2 5 3 0 3 3 1 0 2 2 2 2 5 1 1 1 6 0 0 1 2 3 3 0 4 0 2 4 1 1 1 1 2 3 4 0 1 0 1 2 1 1 2 2 1 1 5 2 2 1 2 2 1 1 4 2 1 3 3 2 0 3 2 5 2 4 1 2 3 1 2 4 0 2 2 1 5 2 2 4 2 1 1 2 1 2 1 1 3 1 1 4 3 4 2 1 7 1 4 0 4 7 3 3 5 1 4 1 1 1 0 1 3</counts>
			</dataPoints>
		</scan>
		<scan appendNumber="0" mode="Continuous" scanAxis="Phi" status="Completed">
			<header>
				<startTimeStamp>2020-09-09T13:01:45+02:00</startTimeStamp>
				<endTimeStamp>2020-09-09T13:04:47+02:00</endTimeStamp>
				<author>
					<name>User</name>
				</author>
				<source>
					<applicationSoftware version="6.1">Data Collector</applicationSoftware>
					<instrumentControlSoftware version="2.2F 20161117">XPERT-PRO</instrumentControlSoftware>
					<instrumentID>0000000011073629</instrumentID>
				</source>
			</header>
			<dataPoints>
				<positions axis="2Theta" unit="deg">
					<commonPosition>29.8800</commonPosition>
				</positions>
				<positions axis="Omega" unit="deg">
					<commonPosition>14.9400</commonPosition>
				</positions>
				<positions axis="Phi" unit="deg">
					<startPosition>0.50</startPosition>
					<endPosition>359.50</endPosition>
				</positions>
				<positions axis="Chi" unit="deg">
					<commonPosition>84.00</commonPosition>
				</positions>
				<positions axis="X" unit="mm">
					<commonPosition>-1.57</commonPosition>
				</positions>
				<positions axis="Y" unit="mm">
					<commonPosition>0.80</commonPosition>
				</positions>
				<positions axis="Z" unit="mm">
					<commonPosition>6.427</commonPosition>
				</positions>
				<commonCountingTime unit="seconds">0.440</commonCountingTime>
				<counts unit="counts">1 1 2 1 4 3 5 0 2 2 4 1 1 2 4 0 2 2 1 2 1 4 3 1 0 2 1 4 2 1 2 1 1 3 1 1 3 3 1 4 3 0 2 0 2 0 1 3 0 5 3 1 2 0 0 2 1 2 1 0 2 2 1 5 3 0 1 2 1 2 1 1 1 3 1 1 0 3 2 2 5 2 2 0 2 1 2 0 1 3 3 4 1 2 0 1 0 0 2 1 5 3 2 2 1 4 2 2 2 1 1 1 1 2 3 0 3 2 2 1 0 0 2 4 1 1 5 3 1 1 2 2 2 1 4 0 2 5 1 2 5 2 6 4 0 2 5 3 3 1 4 1 3 3 1 4 4 2 3 0 0 2 1 3 2 3 0 1 3 1 1 2 2 0 4 1 1 5 3 3 3 3 1 1 2 1 0 3 2 0 0 3 1 2 1 3 6 0 5 0 2 0 1 0 1 1 0 2 2 1 1 2 1 2 4 0 1 2 0 4 1 2 0 3 1 2 4 5 1 0 0 3 1 1 1 1 0 1 1 3 5 1 5 3 1 2 3 2 2 1 0 4 4 3 3 2 1 2 1 0 2 1 2 3 3 2 2 0 1 3 6 1 2 4 3 0 2 2 1 4 4 4 3 4 2 1 2 0 1 3 2 3 1 2 1 5 0 1 4 1 1 5 4 2 2 1 3 2 4 2 3 1 2 1 1 1 1 4 1 1 0 2 1 1 1 2 3 5 9 0 2 0 4 1 1 6 3 3 0 2 0 4 3 4 0 0 4 4 2 4 4 8 1 1 0 0 2 1 0 1</counts>
			</dataPoints>
		</scan>
		<scan appendNumber="0" mode="Continuous" scanAxis="Phi" status="Completed">
			<header>
				<startTimeStamp>2020-09-09T13:04:58+02:00</startTimeStamp>
				<endTimeStamp>2020-09-09T13:08:00+02:00</endTimeStamp>
				<author>
					<name>User</name>
				</author>
				<source>
					<applicationSoftware version="6.1">Data Collector</applicationSoftware>
					<instrumentControlSoftware version="2.2F 20161117">XPERT-PRO</instrumentControlSoftware>
					<instrumentID>0000000011073629</instrumentID>
				</source>
			</header>
			<dataPoints>
				<positions axis="2Theta" unit="deg">
					<commonPosition>29.8800</commonPosition>
				</positions>
				<positions axis="Omega" unit="deg">
					<commonPosition>14.9400</commonPosition>
				</positions>
				<positions axis="Phi" unit="deg">
					<startPosition>0.50</startPosition>
					<endPosition>359.50</endPosition>
				</positions>
				<positions axis="Chi" unit="deg">
					<commonPosition>86.00</commonPosition>
				</positions>
				<positions axis="X" unit="mm">
					<commonPosition>-1.57</commonPosition>
				</positions>
				<positions axis="Y" unit="mm">
					<commonPosition>0.80</commonPosition>
				</positions>
				<positions axis="Z" unit="mm">
					<commonPosition>6.427</commonPosition>
				</positions>
				<commonCountingTime unit="seconds">0.440</commonCountingTime>
				<counts unit="counts">3 1 2 2 3 5 1 1 1 1 1 2 2 1 2 1 2 0 2 5 1 1 3 2 1 3 4 2 2 1 0 1 5 4 4 1 4 3 1 3 1 2 2 1 1 1 4 1 0 1 4 1 2 3 4 3 0 1 1 2 3 4 4 2 3 2 4 2 1 2 1 0 2 1 1 1 0 4 2 2 1 0 3 0 2 2 1 1 1 1 1 0 1 1 2 1 4 1 1 1 0 2 1 3 2 0 1 6 5 4 0 4 0 4 1 0 1 0 1 2 3 0 1 1 1 2 2 3 2 2 0 0 2 1 2 1 2 1 5 2 2 3 1 1 1 2 1 0 4 1 0 1 2 2 3 2 1 3 0 2 1 1 1 0 2 0 2 1 3 1 4 3 3 4 3 0 6 3 1 5 3 2 3 1 3 0 1 0 3 1 2 5 0 1 2 2 2 1 0 1 2 2 1 2 2 0 0 3 2 2 1 1 3 4 0 2 1 1 2 1 1 4 4 2 4 1 1 1 2 2 1 5 4 1 3 3 2 2 1 2 2 4 2 1 0 4 0 1 1 1 2 1 1 2 1 1 1 2 1 3 2 5 3 3 0 1 1 1 3 2 4 0 2 1 1 0 3 0 2 2 1 1 3 3 0 1 0 1 0 2 3 0 2 1 2 1 2 0 6 2 3 1 2 1 0 1 0 1 1 1 3 0 0 4 1 4 0 2 1 2 3 2 3 1 2 2 1 4 1 1 1 1 0 2 2 4 1 2 1 4 2 2 2 2 1 1 4 3 1 3 2 2 1 2 5 1 2 2 1 0</counts>
			</dataPoints>
		</scan>
		<scan appendNumber="0" mode="Continuous" scanAxis="Phi" status="Completed">
			<header>
				<startTimeStamp>2020-09-09T13:08:11+02:00</startTimeStamp>
				<endTimeStamp>2020-09-09T13:11:13+02:00</endTimeStamp>
				<author>
					<name>User</name>
				</author>
				<source>
					<applicationSoftware version="6.1">Data Collector</applicationSoftware>
					<instrumentControlSoftware version="2.2F 20161117">XPERT-PRO</instrumentControlSoftware>
					<instrumentID>0000000011073629</instrumentID>
				</source>
			</header>
			<dataPoints>
				<positions axis="2Theta" unit="deg">
					<commonPosition>29.8800</commonPosition>
				</positions>
				<positions axis="Omega" unit="deg">
					<commonPosition>14.9400</commonPosition>
				</positions>
				<positions axis="Phi" unit="deg">
					<startPosition>0.50</startPosition>
					<endPosition>359.50</endPosition>
				</positions>
				<positions axis="Chi" unit="deg">
					<commonPosition>88.00</commonPosition>
				</positions>
				<positions axis="X" unit="mm">
					<commonPosition>-1.57</commonPosition>
				</positions>
				<positions axis="Y" unit="mm">
					<commonPosition>0.80</commonPosition>
				</positions>
				<positions axis="Z" unit="mm">
					<commonPosition>6.427</commonPosition>
				</positions>
				<commonCountingTime unit="seconds">0.440</commonCountingTime>
				<counts unit="counts">1 1 1 4 0 3 4 1 1 1 4 0 0 1 1 3 1 1 1 3 2 1 0 1 0 2 0 2 3 2 1 2 2 0 1 2 5 2 2 2 1 1 2 1 0 1 1 5 3 3 3 3 3 4 2 3 4 1 1 2 1 0 1 3 3 0 1 2 1 4 0 1 6 2 4 1 4 4 0 5 1 1 5 2 1 2 1 1 1 0 3 1 0 1 1 1 3 2 3 1 0 0 1 4 1 2 0 4 3 1 2 1 0 1 5 1 1 2 1 2 0 1 1 2 2 5 2 2 3 1 0 1 2 1 1 3 2 1 1 0 2 2 2 1 2 1 1 1 1 2 0 0 2 0 5 2 1 1 2 2 1 2 0 2 2 2 2 0 2 1 0 2 5 5 1 2 3 3 1 1 1 4 4 1 4 2 2 4 0 1 1 1 1 2 2 2 4 1 2 1 3 1 0 1 0 1 6 2 4 1 1 1 0 2 4 3 3 2 3 1 1 4 1 1 0 0 3 2 1 3 1 0 2 0 0 4 1 3 2 0 2 2 3 2 3 3 1 4 3 1 2 2 0 1 0 1 4 2 1 2 1 0 1 1 1 4 0 3 1 0 2 3 1 3 0 1 2 3 0 1 3 0 4 5 3 1 0 4 2 0 1 4 4 2 0 1 5 2 1 0 0 7 1 1 1 1 2 3 2 1 1 1 3 0 2 2 4 0 3 3 2 4 2 2 0 0 3 1 0 5 0 2 2 3 1 1 1 3 2 2 3 2 2 3 2 4 1 3 0 2 1 2 3 3 1 1 3 2 2 1</counts>
			</dataPoints>
		</scan>
		<scan appendNumber="0" mode="Continuous" scanAxis="Phi" status="Completed">
			<header>
				<startTimeStamp>2020-09-09T13:11:24+02:00</startTimeStamp>
				<endTimeStamp>2020-09-09T13:14:26+02:00</endTimeStamp>
				<author>
					<name>User</name>
				</author>
				<source>
					<applicationSoftware version="6.1">Data Collector</applicationSoftware>
					<instrumentControlSoftware version="2.2F 20161117">XPERT-PRO</instrumentControlSoftware>
					<instrumentID>0000000011073629</instrumentID>
				</source>
			</header>
			<dataPoints>
				<positions axis="2Theta" unit="deg">
					<commonPosition>29.8800</commonPosition>
				</positions>
				<positions axis="Omega" unit="deg">
					<commonPosition>14.9400</commonPosition>
				</positions>
				<positions axis="Phi" unit="deg">
					<startPosition>0.50</startPosition>
					<endPosition>359.50</endPosition>
				</positions>
				<positions axis="Chi" unit="deg">
					<commonPosition>90.00</commonPosition>
				</positions>
				<positions axis="X" unit="mm">
					<commonPosition>-1.57</commonPosition>
				</positions>
				<positions axis="Y" unit="mm">
					<commonPosition>0.80</commonPosition>
				</positions>
				<positions axis="Z" unit="mm">
					<commonPosition>6.427</commonPosition>
				</positions>
				<commonCountingTime unit="seconds">0.440</commonCountingTime>
				<counts unit="counts">1 0 1 4 3 1 2 1 0 2 4 0 3 6 0 2 1 2 6 1 0 2 1 1 1 2 0 0 2 1 2 3 0 2 1 1 2 1 4 3 0 1 1 1 2 2 1 0 3 4 1 2 1 2 3 2 3 1 2 2 1 1 1 1 2 1 3 1 1 2 1 0 2 2 0 2 1 2 1 0 1 2 0 1 1 0 0 1 2 0 2 2 1 0 2 3 2 1 1 2 2 1 1 1 1 3 2 2 1 2 0 3 2 0 3 2 3 2 2 6 0 3 2 1 0 2 3 5 0 1 1 3 4 2 0 0 0 2 1 4 1 0 4 0 2 1 2 5 1 1 2 2 3 0 3 1 2 0 2 1 3 4 5 0 3 1 1 4 1 0 0 0 0 0 0 1 0 1 1 2 2 0 0 3 3 3 0 0 1 2 1 1 1 2 1 0 2 0 1 0 0 2 1 3 1 2 4 3 3 5 0 2 3 2 0 2 0 3 2 0 0 4 0 1 0 1 2 1 1 2 1 0 2 0 1 1 2 0 3 0 7 2 4 4 1 3 4 2 2 0 1 1 1 3 0 3 1 5 2 0 0 2 1 0 3 5 0 4 1 1 1 2 2 0 2 3 1 2 3 2 1 3 1 1 0 1 0 1 3 1 2 1 0 0 2 1 0 4 1 1 4 1 3 0 1 2 2 2 0 1 6 0 1 1 0 2 3 5 0 2 4 4 1 1 1 1 2 2 2 1 1 2 0 2 1 5 2 1 2 0 2 2 3 1 0 2 1 1 3 2 6 1 2 2 1 1 2 4 1 2</counts>
			</dataPoints>
		</scan>
	</xrdMeasurement>
</xrdMeasurements>